Workbook

Sheet Cover
A1: TownCore long-range plan, FY2027-FY2031
A2: AI-written local news sites with a daily newsletter and a local business directory.
A4: Scenario in use | C4: =INDEX({"Downside","Base","Upside"},1,Assumptions!$C$5) -> Base
A6: Summary | C6: 2027 | D6: 2028 | E6: 2029 | F6: 2030 | G6: 2031
A7: Live towns at year end | C7: =Rollout!C7 -> 20 | D7: =Rollout!D7 -> 99.4 | E7: =Rollout!E7 -> 296.6 | F7: =Rollout!F7 -> 688.8 | G7: =Rollout!G7 -> 1371.8
A8: Newsletter subscribers | C8: =KPIs!C8 -> 4200 | D8: =KPIs!D8 -> 27664 | E8: =KPIs!E8 -> 101416 | F8: =KPIs!F8 -> 276220 | G8: =KPIs!G8 -> 624974
A9: Revenue ($) | C9: ='P&L'!C5 -> 18028.56 | D9: ='P&L'!D5 -> 217104.87 | E9: ='P&L'!E5 -> 1084578.1 | F9: ='P&L'!F5 -> 3547798 | G9: ='P&L'!G5 -> 9061606.7
A10: Gross margin | C10: ='P&L'!C8 -> 0.5581525 | D10: ='P&L'!D8 -> 0.77079368 | E10: ='P&L'!E8 -> 0.84164504 | F10: ='P&L'!F8 -> 0.87517928 | G10: ='P&L'!G8 -> 0.89447292
A11: EBITDA ($) | C11: ='P&L'!C16 -> -1221781.3 | D11: ='P&L'!D16 -> -2165908.7 | E11: ='P&L'!E16 -> -3533796.5 | F11: ='P&L'!F16 -> -5134437.4 | G11: ='P&L'!G16 -> -6049621.9
A12: EBITDA margin | C12: ='P&L'!C17 -> -67.769213 | D12: ='P&L'!D17 -> -9.9763247 | E12: ='P&L'!E17 -> -3.2582221 | F12: ='P&L'!F17 -> -1.4472181 | G12: ='P&L'!G17 -> -0.66761029
A13: Net income ($) | C13: ='P&L'!C25 -> -1229281.3 | D13: ='P&L'!D25 -> -2179242 | E13: ='P&L'!E25 -> -3562129.8 | F13: ='P&L'!F25 -> -5181104.1 | G13: ='P&L'!G25 -> -6132955.3
A14: Closing cash ($) | C14: ='Cash Flow'!C13 -> 1005177.8 | D14: ='Cash Flow'!D13 -> 6815796.8 | E14: ='Cash Flow'!E13 -> 3210976.2 | F14: ='Cash Flow'!F13 -> 12925142 | G14: ='Cash Flow'!G13 -> 6582606
A15: Run-rate EBITDA at maturity ($) | C15: =KPIs!C22 -> -613580.35 | D15: =KPIs!D22 -> 294083.18 | E15: =KPIs!E22 -> 3244622.2 | F15: =KPIs!F22 -> 9695346.4 | G15: =KPIs!G22 -> 21904050
A17: How to use
A18: 1. Change inputs only on the Assumptions tab: blue text is an input, yellow fill a key assumption.
A19: 2. Switch scenarios with Assumptions "Active scenario" (1 Downside, 2 Base, 3 Upside).
A20: 3. Black text is a formula; green text links to another tab. Don't overwrite formulas.
A21: 4. Unit Economics shows one average town by age (Age 1 = launch year). Revenue and Costs add up each year's launch cohorts at their age.
A22: 5. Prices, story budgets, AI caps and directory counts come from the TownCore repo (CLAUDE.md and town config); everything marked "Estimate" in Assumptions column H is a planning assumption to validate.
A23: 6. Not modeled: programmatic consent costs, a licensed sports-data feed (not yet bought), office space, debt, and acquisitions.
A25: Color legend
A26: Input
A27: Key assumption
A28: Formula
A29: Link to another tab

Sheet Assumptions
A1: TownCore LRP: assumptions
A2: Blue = input you can change. Yellow = key assumption. Every other tab is formulas over this one. Columns C-G are years (2027-2031) or a town's age in years (Age 1 = launch year), as each block's header says.
A4: Scenario
A5: Active scenario (1 = Downside, 2 = Base, 3 = Upside) | C5: 2 | H5: Pick 1, 2 or 3. The multipliers below scale launches, audience, monetization and unit costs.
C6: Downside | D6: Base | E6: Upside | F6: Active
A7: Town launches multiplier | C7: 0.6 | D7: 1 | E7: 1.3 | F7: =INDEX(C7:E7,1,Assumptions!$C$5) -> 1 | H7: Scales the launch schedule.
A8: Audience multiplier | C8: 0.7 | D8: 1 | E8: 1.25 | F8: =INDEX(C8:E8,1,Assumptions!$C$5) -> 1 | H8: Scales subscriber penetration and pageviews.
A9: Monetization multiplier | C9: 0.7 | D9: 1 | E9: 1.2 | F9: =INDEX(C9:E9,1,Assumptions!$C$5) -> 1 | H9: Scales fill, sell-through and conversion rates.
A10: Unit cost multiplier | C10: 1.2 | D10: 1 | E10: 0.9 | F10: =INDEX(C10:E10,1,Assumptions!$C$5) -> 1 | H10: Scales per-town direct costs and launch costs.
A12: Town rollout (by fiscal year)
A13: Fiscal year | C13: 2027 | D13: 2028 | E13: 2029 | F13: 2030 | G13: 2031
A14: New towns launched (base case) | B14: towns | C14: 20 | D14: 80 | E14: 200 | F14: 400 | G14: 700 | H14: Management target; CLAUDE.md goal is thousands of towns, one command per launch. Scaled by the launch multiplier.
A16: Town size mix and size-driven inputs (CLAUDE.md §5 tiers)
C17: Small | D17: Mid | E17: Large | F17: Weighted
A18: Share of launches | C18: 0.5 | D18: 0.35 | E18: 0.15 | F18: =SUM(C18:E18) -> 1 | H18: Ranked list (CLAUDE.md §10a) skews to smaller towns; population floor 5,000.
A19: Households per town | C19: 4000 | D19: 15000 | E19: 45000 | F19: =SUMPRODUCT(C19:E19,$C$18:$E$18) -> 14000 | H19: Estimate from Census place sizes; Boca Raton (large) is roughly 45,000 households.
A20: Directory listings per town | C20: 300 | D20: 900 | E20: 2300 | F20: =SUMPRODUCT(C20:E20,$C$18:$E$18) -> 810 | H20: Boca live data 2026-10-16: 2,334 active listings (1,979 state licenses + 355 mapped). Small and mid scaled down; estimate.
A21: Stories per day (story budget) | C21: 3 | D21: 6 | E21: 10 | F21: =SUMPRODUCT(C21:E21,$C$18:$E$18) -> 5.1 | H21: CLAUDE.md D-M3-7: daily story budget 3 / 6 / 10 by tier.
A22: Town sponsor banner price ($/month) | C22: 150 | D22: 400 | E22: 900 | F22: =SUMPRODUCT(C22:E22,$C$18:$E$18) -> 350 | H22: Direct-sold home.top sponsor (§11b). Estimate; local banner rates vary widely.
A24: Audience (by town age; Age 1 = launch year)
A25: Town age | C25: Age 1 | D25: Age 2 | E25: Age 3 | F25: Age 4 | G25: Age 5
A26: Newsletter subscribers as % of households | C26: 0.015 | D26: 0.04 | E26: 0.06 | F26: 0.075 | G26: 0.085 | H26: Estimate. Mature local newsletters report reaching roughly 5-15% of households; scaled by the audience multiplier.
A27: Monthly pageviews per household | C27: 1 | D27: 2 | E27: 3 | F27: 3.5 | G27: 4 | H27: Estimate; driven by search, Facebook and the daily newsletter. Scaled by audience multiplier.
A28: Share of launched towns still live | C28: 1 | D28: 0.97 | E28: 0.95 | F28: 0.94 | G28: 0.93 | H28: Rule 7: towns that fall below readiness are paused. Estimate.
A30: Monetization (by town age)
A31: Town age | C31: Age 1 | D31: Age 2 | E31: Age 3 | F31: Age 4 | G31: Age 5
A32: Featured directory spots filled (% of 3 per category) | C32: 0.05 | D32: 0.15 | E32: 0.25 | F32: 0.32 | G32: 0.38 | H32: Estimate. Spots #1/#2/#3 per category (§11). Scaled by monetization multiplier.
A33: Listings claimed (cumulative %) | C33: 0.02 | D33: 0.05 | E33: 0.08 | F33: 0.1 | G33: 0.12 | H33: Estimate; claim flow by email confirmation (M6).
A34: Claimed listings buying Enhanced (%) | C34: 0.08 | D34: 0.12 | E34: 0.15 | F34: 0.17 | G34: 0.18 | H34: Estimate. Scaled by monetization multiplier.
A35: Newsletter sponsorship sell-through | C35: 0.1 | D35: 0.3 | E35: 0.45 | F35: 0.55 | G35: 0.6 | H35: Share of issues with a paid presenting sponsor (§11b newsletter.top). Estimate.
A36: Town sponsor banner sell-through | C36: 0.1 | D36: 0.3 | E36: 0.5 | F36: 0.6 | G36: 0.65 | H36: Share of months the home.top banner is direct-sold. Estimate.
A37: Category sponsorships sold (% of categories) | C37: 0 | D37: 0.02 | E37: 0.05 | F37: 0.08 | G37: 0.1 | H37: category.sponsor / exclusive (§11b); built but off at launch (D-M6-6), so Age 1 = 0.
A38: Programmatic ads switched on (1 = yes) | C38: 0 | D38: 0 | E38: 1 | F38: 1 | G38: 1 | H38: Gated: only after a town passes Gate 2 with steady traffic (§11b). Assumed from Age 3.
A40: Prices and rates
A41: Directory categories per town | B41: count | C41: 28 | H41: packages/config/src/directory.ts lists 28 categories.
A42: Featured spots #1 + #2 + #3 per category | B42: $/month | C42: 38 | H42: Town config pricing.featured_usd [19, 12, 7] (owner, 2026-10-16).
A43: Free trial on a first featured spot | B43: days | C43: 30 | H43: Town config free_trial_days: 30.
A44: Revenue lost to trials (share of featured revenue) | C44: 0.08 | H44: Estimate: one free month per new spot over an average spot life of about a year.
A45: Enhanced listing price | B45: $/month | C45: 39 | H45: Town config pricing.enhanced_usd: 39.
A46: Category sponsorship price | B46: $/month | C46: 99 | H46: Estimate; price not yet set by the owner (M6 open item).
...

Sheet Rollout
A1: Town rollout
A2: Launches by year and live towns, from Assumptions.
A4: Fiscal year | C4: 2027 | D4: 2028 | E4: 2029 | F4: 2030 | G4: 2031
A5: New towns launched | C5: =ROUND(Assumptions!C$14*Assumptions!$F$7,0) -> 20 | D5: =ROUND(Assumptions!D$14*Assumptions!$F$7,0) -> 80 | E5: =ROUND(Assumptions!E$14*Assumptions!$F$7,0) -> 200 | F5: =ROUND(Assumptions!F$14*Assumptions!$F$7,0) -> 400 | G5: =ROUND(Assumptions!G$14*Assumptions!$F$7,0) -> 700
A6: Cumulative towns launched | C6: =C5 -> 20 | D6: =C6+D5 -> 100 | E6: =D6+E5 -> 300 | F6: =E6+F5 -> 700 | G6: =F6+G5 -> 1400
A7: Live towns at year end | C7: =C$5*Assumptions!$C$28 -> 20 | D7: =C$5*Assumptions!$D$28+D$5*Assumptions!$C$28 -> 99.4 | E7: =C$5*Assumptions!$E$28+D$5*Assumptions!$D$28+E$5*Assumptions!$C$28 -> 296.6 | F7: =C$5*Assumptions!$F$28+D$5*Assumptions!$E$28+E$5*Assumptions!$D$28+F$5*Assumptions!$C$28 -> 688.8 | G7: =C$5*Assumptions!$G$28+D$5*Assumptions!$F$28+E$5*Assumptions!$E$28+F$5*Assumptions!$D$28+G$5*Assumptions!$C$28 -> 1371.8 | H7: Launches x share still live at each age.
A8: Average live towns in year | C8: =C7/2 -> 10 | D8: =(C7+D7)/2 -> 59.7 | E8: =(D7+E7)/2 -> 198 | F8: =(E7+F7)/2 -> 492.7 | G8: =(F7+G7)/2 -> 1030.3 | H8: Used for people ratios.

Sheet Unit Economics
A1: Unit economics: one average launched town, by age
A2: Age 1 is the launch year (half a year live on average). Values per launched town, already weighted by the share of towns still live. Network totals on Revenue and Costs multiply these by each year's launch cohorts.
A4: Town age | C4: Age 1 | D4: Age 2 | E4: Age 3 | F4: Age 4 | G4: Age 5
A5: Time live and survival
A6: Share of the year live | C6: =0.5 -> 0.5 | D6: =1 -> 1 | E6: =1 -> 1 | F6: =1 -> 1 | G6: =1 -> 1 | H6: Launches spread across the year, so a town is live about half its launch year.
A7: Share of launched towns still live | C7: =Assumptions!C$28 -> 1 | D7: =Assumptions!D$28 -> 0.97 | E7: =Assumptions!E$28 -> 0.95 | F7: =Assumptions!F$28 -> 0.94 | G7: =Assumptions!G$28 -> 0.93
A8: Live town-years per launched town | C8: =C6*C7 -> 0.5 | D8: =D6*D7 -> 0.97 | E8: =E6*E7 -> 0.95 | F8: =F6*F7 -> 0.94 | G8: =G6*G7 -> 0.93
A9: Audience
A10: Newsletter subscribers (year end) | C10: =Assumptions!$F$19*Assumptions!C$26*Assumptions!$F$8*C7 -> 210 | D10: =Assumptions!$F$19*Assumptions!D$26*Assumptions!$F$8*D7 -> 543.2 | E10: =Assumptions!$F$19*Assumptions!E$26*Assumptions!$F$8*E7 -> 798 | F10: =Assumptions!$F$19*Assumptions!F$26*Assumptions!$F$8*F7 -> 987 | G10: =Assumptions!$F$19*Assumptions!G$26*Assumptions!$F$8*G7 -> 1106.7
A11: New subscribers in the year | C11: =C10 -> 210 | D11: =MAX(0,D10-C10) -> 333.2 | E11: =MAX(0,E10-D10) -> 254.8 | F11: =MAX(0,F10-E10) -> 189 | G11: =MAX(0,G10-F10) -> 119.7
A12: Pageviews in the year | C12: =Assumptions!$F$19*Assumptions!C$27*Assumptions!$F$8*12*C8 -> 84000 | D12: =Assumptions!$F$19*Assumptions!D$27*Assumptions!$F$8*12*D8 -> 325920 | E12: =Assumptions!$F$19*Assumptions!E$27*Assumptions!$F$8*12*E8 -> 478800 | F12: =Assumptions!$F$19*Assumptions!F$27*Assumptions!$F$8*12*F8 -> 552720 | G12: =Assumptions!$F$19*Assumptions!G$27*Assumptions!$F$8*12*G8 -> 624960
A13: Directory
A14: Featured spots sold (average) | C14: =Assumptions!$C$41*3*MIN(1,Assumptions!C$32*Assumptions!$F$9)*C7 -> 4.2 | D14: =Assumptions!$C$41*3*MIN(1,Assumptions!D$32*Assumptions!$F$9)*D7 -> 12.222 | E14: =Assumptions!$C$41*3*MIN(1,Assumptions!E$32*Assumptions!$F$9)*E7 -> 19.95 | F14: =Assumptions!$C$41*3*MIN(1,Assumptions!F$32*Assumptions!$F$9)*F7 -> 25.2672 | G14: =Assumptions!$C$41*3*MIN(1,Assumptions!G$32*Assumptions!$F$9)*G7 -> 29.6856
A15: Enhanced listings (average) | C15: =Assumptions!$F$20*Assumptions!C$33*MIN(1,Assumptions!C$34*Assumptions!$F$9)*C7 -> 1.296 | D15: =Assumptions!$F$20*Assumptions!D$33*MIN(1,Assumptions!D$34*Assumptions!$F$9)*D7 -> 4.7142 | E15: =Assumptions!$F$20*Assumptions!E$33*MIN(1,Assumptions!E$34*Assumptions!$F$9)*E7 -> 9.234 | F15: =Assumptions!$F$20*Assumptions!F$33*MIN(1,Assumptions!F$34*Assumptions!$F$9)*F7 -> 12.9438 | G15: =Assumptions!$F$20*Assumptions!G$33*MIN(1,Assumptions!G$34*Assumptions!$F$9)*G7 -> 16.27128
A16: Category sponsorships (average) | C16: =Assumptions!$C$41*MIN(1,Assumptions!C$37*Assumptions!$F$9)*C7 -> 0 | D16: =Assumptions!$C$41*MIN(1,Assumptions!D$37*Assumptions!$F$9)*D7 -> 0.5432 | E16: =Assumptions!$C$41*MIN(1,Assumptions!E$37*Assumptions!$F$9)*E7 -> 1.33 | F16: =Assumptions!$C$41*MIN(1,Assumptions!F$37*Assumptions!$F$9)*F7 -> 2.1056 | G16: =Assumptions!$C$41*MIN(1,Assumptions!G$37*Assumptions!$F$9)*G7 -> 2.604
A17: Paying directory businesses (average) | C17: =C14+C15+C16 -> 5.496 | D17: =D14+D15+D16 -> 17.4794 | E17: =E14+E15+E16 -> 30.514 | F17: =F14+F15+F16 -> 40.3166 | G17: =G14+G15+G16 -> 48.56088 | H17: Counts each paid product once; a business can hold more than one.
A18: Revenue per launched town ($)
A19: Featured directory spots | C19: =C14/3*Assumptions!$C$42*12*(1-Assumptions!$C$44)*C6 -> 293.664 | D19: =D14/3*Assumptions!$C$42*12*(1-Assumptions!$C$44)*D6 -> 1709.1245 | E19: =E14/3*Assumptions!$C$42*12*(1-Assumptions!$C$44)*E6 -> 2789.808 | F19: =F14/3*Assumptions!$C$42*12*(1-Assumptions!$C$44)*F6 -> 3533.3652 | G19: =G14/3*Assumptions!$C$42*12*(1-Assumptions!$C$44)*G6 -> 4151.2343 | H19: Spots x average price ($38 / 3) x 12, less free-trial months.
A20: Enhanced listings | C20: =C15*Assumptions!$C$45*12*C6 -> 303.264 | D20: =D15*Assumptions!$C$45*12*D6 -> 2206.2456 | E20: =E15*Assumptions!$C$45*12*E6 -> 4321.512 | F20: =F15*Assumptions!$C$45*12*F6 -> 6057.6984 | G20: =G15*Assumptions!$C$45*12*G6 -> 7614.959
A21: Category sponsorships | C21: =C16*Assumptions!$C$46*12*C6 -> 0 | D21: =D16*Assumptions!$C$46*12*D6 -> 645.3216 | E21: =E16*Assumptions!$C$46*12*E6 -> 1580.04 | F21: =F16*Assumptions!$C$46*12*F6 -> 2501.4528 | G21: =G16*Assumptions!$C$46*12*G6 -> 3093.552
A22: Newsletter sponsorships | C22: =C10/1000*Assumptions!$C$48*Assumptions!$C$47*MIN(1,Assumptions!C$35*Assumptions!$F$9)*C6 -> 94.5 | D22: =D10/1000*Assumptions!$C$48*Assumptions!$C$47*MIN(1,Assumptions!D$35*Assumptions!$F$9)*D6 -> 1466.64 | E22: =E10/1000*Assumptions!$C$48*Assumptions!$C$47*MIN(1,Assumptions!E$35*Assumptions!$F$9)*E6 -> 3231.9 | F22: =F10/1000*Assumptions!$C$48*Assumptions!$C$47*MIN(1,Assumptions!F$35*Assumptions!$F$9)*F6 -> 4885.65 | G22: =G10/1000*Assumptions!$C$48*Assumptions!$C$47*MIN(1,Assumptions!G$35*Assumptions!$F$9)*G6 -> 5976.18 | H22: Subscribers / 1,000 x CPM x issues x sell-through.
A23: Town sponsor banner | C23: =Assumptions!$F$22*12*MIN(1,Assumptions!C$36*Assumptions!$F$9)*C8 -> 210 | D23: =Assumptions!$F$22*12*MIN(1,Assumptions!D$36*Assumptions!$F$9)*D8 -> 1222.2 | E23: =Assumptions!$F$22*12*MIN(1,Assumptions!E$36*Assumptions!$F$9)*E8 -> 1995 | F23: =Assumptions!$F$22*12*MIN(1,Assumptions!F$36*Assumptions!$F$9)*F8 -> 2368.8 | G23: =Assumptions!$F$22*12*MIN(1,Assumptions!G$36*Assumptions!$F$9)*G8 -> 2538.9
A24: Programmatic display | C24: =C12/1000*Assumptions!$C$49*Assumptions!$C$50*Assumptions!C$38 -> 0 | D24: =D12/1000*Assumptions!$C$49*Assumptions!$C$50*Assumptions!D$38 -> 0 | E24: =E12/1000*Assumptions!$C$49*Assumptions!$C$50*Assumptions!E$38 -> 2298.24 | F24: =F12/1000*Assumptions!$C$49*Assumptions!$C$50*Assumptions!F$38 -> 2653.056 | G24: =G12/1000*Assumptions!$C$49*Assumptions!$C$50*Assumptions!G$38 -> 2999.808
A25: Total revenue per launched town | C25: =SUM(C19:C24) -> 901.428 | D25: =SUM(D19:D24) -> 7249.5317 | E25: =SUM(E19:E24) -> 16216.5 | F25: =SUM(F19:F24) -> 22000.022 | G25: =SUM(G19:G24) -> 26374.633
A26: of which directory (self-serve, Stripe) | C26: =C19+C20 -> 596.928 | D26: =D19+D20 -> 3915.3701 | E26: =E19+E20 -> 7111.32 | F26: =F19+F20 -> 9591.0636 | G26: =G19+G20 -> 11766.193
A27: of which direct-sold (commissionable) | C27: =C21+C22+C23 -> 304.5 | D27: =D21+D22+D23 -> 3334.1616 | E27: =E21+E22+E23 -> 6806.94 | F27: =F21+F22+F23 -> 9755.9028 | G27: =G21+G22+G23 -> 11608.632
A28: Direct costs per launched town ($)
A29: AI (writing and fact-checking) | C29: =MIN(Assumptions!$C$55,Assumptions!$F$21*Assumptions!$C$53+Assumptions!$C$54)*Assumptions!$F$10*365*C8 -> 202.94 | D29: =MIN(Assumptions!$C$55,Assumptions!$F$21*Assumptions!$C$53+Assumptions!$C$54)*Assumptions!$F$10*365*D8 -> 393.7036 | E29: =MIN(Assumptions!$C$55,Assumptions!$F$21*Assumptions!$C$53+Assumptions!$C$54)*Assumptions!$F$10*365*E8 -> 385.586 | F29: =MIN(Assumptions!$C$55,Assumptions!$F$21*Assumptions!$C$53+Assumptions!$C$54)*Assumptions!$F$10*365*F8 -> 381.5272 | G29: =MIN(Assumptions!$C$55,Assumptions!$F$21*Assumptions!$C$53+Assumptions!$C$54)*Assumptions!$F$10*365*G8 -> 377.4684 | H29: Stories a day x cost a story + overhead, capped at the daily cap.
A30: Hosting, database and data | C30: =Assumptions!$C$56*12*Assumptions!$F$10*C8 -> 150 | D30: =Assumptions!$C$56*12*Assumptions!$F$10*D8 -> 291 | E30: =Assumptions!$C$56*12*Assumptions!$F$10*E8 -> 285 | F30: =Assumptions!$C$56*12*Assumptions!$F$10*F8 -> 282 | G30: =Assumptions!$C$56*12*Assumptions!$F$10*G8 -> 279
A31: Email sending | C31: =C10*Assumptions!$C$47/1000*Assumptions!$C$57*C6 -> 3.15 | D31: =D10*Assumptions!$C$47/1000*Assumptions!$C$57*D6 -> 16.296 | E31: =E10*Assumptions!$C$47/1000*Assumptions!$C$57*E6 -> 23.94 | F31: =F10*Assumptions!$C$47/1000*Assumptions!$C$57*F6 -> 29.61 | G31: =G10*Assumptions!$C$47/1000*Assumptions!$C$57*G6 -> 33.201
A32: Card processing | C32: =C26*Assumptions!$C$58+(C14+C15)*12*Assumptions!$C$59*C6 -> 27.203712 | D32: =D26*Assumptions!$C$58+(D14+D15)*12*Assumptions!$C$59*D6 -> 174.51605 | E32: =E26*Assumptions!$C$58+(E14+E15)*12*Assumptions!$C$59*E6 -> 311.29068 | F32: =F26*Assumptions!$C$58+(F14+F15)*12*Assumptions!$C$59*F6 -> 415.70045 | G32: =G26*Assumptions!$C$58+(G14+G15)*12*Assumptions!$C$59*G6 -> 506.66437
A33: Domain renewal | C33: =0 -> 0 | D33: =Assumptions!$C$60*D7 -> 19.4 | E33: =Assumptions!$C$60*E7 -> 19 | F33: =Assumptions!$C$60*F7 -> 18.8 | G33: =Assumptions!$C$60*G7 -> 18.6 | H33: Bought at launch (launch costs); renewed from Age 2.
A34: Total direct costs | C34: =SUM(C29:C33) -> 383.29371 | D34: =SUM(D29:D33) -> 894.91565 | E34: =SUM(E29:E33) -> 1024.8167 | F34: =SUM(F29:F33) -> 1127.6376 | G34: =SUM(G29:G33) -> 1214.9338
A35: Gross profit per launched town | C35: =C25-C34 -> 518.13429 | D35: =D25-D34 -> 6354.616 | E35: =E25-E34 -> 15191.683 | F35: =F25-F34 -> 20872.385 | G35: =G25-G34 -> 25159.7
A36: Gross margin | C36: =IF(C25=0,0,C35/C25) -> 0.57479276 | D36: =IF(D25=0,0,D35/D25) -> 0.87655538 | E36: =IF(E25=0,0,E35/E25) -> 0.93680408 | F36: =IF(F25=0,0,F35/F25) -> 0.9487438 | G36: =IF(G25=0,0,G35/G25) -> 0.95393552
A37: Town-level people and acquisition costs ($)
A38: Editorial review (share of a reviewer) | C38: =Assumptions!$C$78*(1+Assumptions!$C$68)/Assumptions!$C$71*C8 -> 1093.75 | D38: =Assumptions!$C$78*(1+Assumptions!$C$68)/Assumptions!$C$71*D8 -> 2121.875 | E38: =Assumptions!$C$78*(1+Assumptions!$C$68)/Assumptions!$C$71*E8 -> 2078.125 | F38: =Assumptions!$C$78*(1+Assumptions!$C$68)/Assumptions!$C$71*F8 -> 2056.25 | G38: =Assumptions!$C$78*(1+Assumptions!$C$68)/Assumptions!$C$71*G8 -> 2034.375
A39: Local sales (share of an AE) + commission | C39: =Assumptions!$C$79*(1+Assumptions!$C$68)/Assumptions!$C$72*C8+C27*Assumptions!$C$70 -> 1384.6167 | D39: =Assumptions!$C$79*(1+Assumptions!$C$68)/Assumptions!$C$72*D8+D27*Assumptions!$C$70 -> 2960.4995 | E39: =Assumptions!$C$79*(1+Assumptions!$C$68)/Assumptions!$C$72*E8+E27*Assumptions!$C$70 -> 3253.6107 | F39: =Assumptions!$C$79*(1+Assumptions!$C$68)/Assumptions!$C$72*F8+F27*Assumptions!$C$70 -> 3521.4236 | G39: =Assumptions!$C$79*(1+Assumptions!$C$68)/Assumptions!$C$72*G8+G27*Assumptions!$C$70 -> 3679.6132
A40: Support and success (share) | C40: =Assumptions!$C$80*(1+Assumptions!$C$68)/Assumptions!$C$73*C8 -> 286.45833 | D40: =Assumptions!$C$80*(1+Assumptions!$C$68)/Assumptions!$C$73*D8 -> 555.72917 | E40: =Assumptions!$C$80*(1+Assumptions!$C$68)/Assumptions!$C$73*E8 -> 544.27083 | F40: =Assumptions!$C$80*(1+Assumptions!$C$68)/Assumptions!$C$73*F8 -> 538.54167 | G40: =Assumptions!$C$80*(1+Assumptions!$C$68)/Assumptions!$C$73*G8 -> 532.8125
A41: Paid subscriber acquisition | C41: =C11*Assumptions!$C$65*Assumptions!$C$64 -> 168 | D41: =D11*Assumptions!$C$65*Assumptions!$C$64 -> 266.56 | E41: =E11*Assumptions!$C$65*Assumptions!$C$64 -> 203.84 | F41: =F11*Assumptions!$C$65*Assumptions!$C$64 -> 151.2 | G41: =G11*Assumptions!$C$65*Assumptions!$C$64 -> 95.76
...

Sheet Revenue
A1: Revenue build ($)
A2: Network totals: each year's launch cohorts x the per-town values at their age.
A4: Fiscal year | C4: 2027 | D4: 2028 | E4: 2029 | F4: 2030 | G4: 2031
A5: Featured directory spots | C5: =Rollout!$C$5*'Unit Economics'!$C$19 -> 5873.28 | D5: =Rollout!$C$5*'Unit Economics'!$D$19+Rollout!$D$5*'Unit Economics'!$C$19 -> 57675.61 | E5: =Rollout!$C$5*'Unit Economics'!$E$19+Rollout!$D$5*'Unit Economics'!$D$19+Rollout!$E$5*'Unit Economics'!$C$19 -> 251258.92 | F5: =Rollout!$C$5*'Unit Economics'!$F$19+Rollout!$D$5*'Unit Economics'!$E$19+Rollout!$E$5*'Unit Economics'!$D$19+Rollout!$F$5*'Unit Economics'!$C$19 -> 753142.44 | G5: =Rollout!$C$5*'Unit Economics'!$G$19+Rollout!$D$5*'Unit Economics'!$F$19+Rollout!$E$5*'Unit Economics'!$E$19+Rollout!$F$5*'Unit Economics'!$D$19+Rollout!$G$5*'Unit Economics'!$C$19 -> 1812870.1
A6: Enhanced listings | C6: =Rollout!$C$5*'Unit Economics'!$C$20 -> 6065.28 | D6: =Rollout!$C$5*'Unit Economics'!$D$20+Rollout!$D$5*'Unit Economics'!$C$20 -> 68386.032 | E6: =Rollout!$C$5*'Unit Economics'!$E$20+Rollout!$D$5*'Unit Economics'!$D$20+Rollout!$E$5*'Unit Economics'!$C$20 -> 323582.69 | F6: =Rollout!$C$5*'Unit Economics'!$F$20+Rollout!$D$5*'Unit Economics'!$E$20+Rollout!$E$5*'Unit Economics'!$D$20+Rollout!$F$5*'Unit Economics'!$C$20 -> 1029429.6 | G6: =Rollout!$C$5*'Unit Economics'!$G$20+Rollout!$D$5*'Unit Economics'!$F$20+Rollout!$E$5*'Unit Economics'!$E$20+Rollout!$F$5*'Unit Economics'!$D$20+Rollout!$G$5*'Unit Economics'!$C$20 -> 2596000.5
A7: Category sponsorships | C7: =Rollout!$C$5*'Unit Economics'!$C$21 -> 0 | D7: =Rollout!$C$5*'Unit Economics'!$D$21+Rollout!$D$5*'Unit Economics'!$C$21 -> 12906.432 | E7: =Rollout!$C$5*'Unit Economics'!$E$21+Rollout!$D$5*'Unit Economics'!$D$21+Rollout!$E$5*'Unit Economics'!$C$21 -> 83226.528 | F7: =Rollout!$C$5*'Unit Economics'!$F$21+Rollout!$D$5*'Unit Economics'!$E$21+Rollout!$E$5*'Unit Economics'!$D$21+Rollout!$F$5*'Unit Economics'!$C$21 -> 305496.58 | G7: =Rollout!$C$5*'Unit Economics'!$G$21+Rollout!$D$5*'Unit Economics'!$F$21+Rollout!$E$5*'Unit Economics'!$E$21+Rollout!$F$5*'Unit Economics'!$D$21+Rollout!$G$5*'Unit Economics'!$C$21 -> 836123.9
A8: Newsletter sponsorships | C8: =Rollout!$C$5*'Unit Economics'!$C$22 -> 1890 | D8: =Rollout!$C$5*'Unit Economics'!$D$22+Rollout!$D$5*'Unit Economics'!$C$22 -> 36892.8 | E8: =Rollout!$C$5*'Unit Economics'!$E$22+Rollout!$D$5*'Unit Economics'!$D$22+Rollout!$E$5*'Unit Economics'!$C$22 -> 200869.2 | F8: =Rollout!$C$5*'Unit Economics'!$F$22+Rollout!$D$5*'Unit Economics'!$E$22+Rollout!$E$5*'Unit Economics'!$D$22+Rollout!$F$5*'Unit Economics'!$C$22 -> 687393 | G8: =Rollout!$C$5*'Unit Economics'!$G$22+Rollout!$D$5*'Unit Economics'!$F$22+Rollout!$E$5*'Unit Economics'!$E$22+Rollout!$F$5*'Unit Economics'!$D$22+Rollout!$G$5*'Unit Economics'!$C$22 -> 1809561.6
A9: Town sponsor banners | C9: =Rollout!$C$5*'Unit Economics'!$C$23 -> 4200 | D9: =Rollout!$C$5*'Unit Economics'!$D$23+Rollout!$D$5*'Unit Economics'!$C$23 -> 41244 | E9: =Rollout!$C$5*'Unit Economics'!$E$23+Rollout!$D$5*'Unit Economics'!$D$23+Rollout!$E$5*'Unit Economics'!$C$23 -> 179676 | F9: =Rollout!$C$5*'Unit Economics'!$F$23+Rollout!$D$5*'Unit Economics'!$E$23+Rollout!$E$5*'Unit Economics'!$D$23+Rollout!$F$5*'Unit Economics'!$C$23 -> 535416 | G9: =Rollout!$C$5*'Unit Economics'!$G$23+Rollout!$D$5*'Unit Economics'!$F$23+Rollout!$E$5*'Unit Economics'!$E$23+Rollout!$F$5*'Unit Economics'!$D$23+Rollout!$G$5*'Unit Economics'!$C$23 -> 1275162
A10: Programmatic display | C10: =Rollout!$C$5*'Unit Economics'!$C$24 -> 0 | D10: =Rollout!$C$5*'Unit Economics'!$D$24+Rollout!$D$5*'Unit Economics'!$C$24 -> 0 | E10: =Rollout!$C$5*'Unit Economics'!$E$24+Rollout!$D$5*'Unit Economics'!$D$24+Rollout!$E$5*'Unit Economics'!$C$24 -> 45964.8 | F10: =Rollout!$C$5*'Unit Economics'!$F$24+Rollout!$D$5*'Unit Economics'!$E$24+Rollout!$E$5*'Unit Economics'!$D$24+Rollout!$F$5*'Unit Economics'!$C$24 -> 236920.32 | G10: =Rollout!$C$5*'Unit Economics'!$G$24+Rollout!$D$5*'Unit Economics'!$F$24+Rollout!$E$5*'Unit Economics'!$E$24+Rollout!$F$5*'Unit Economics'!$D$24+Rollout!$G$5*'Unit Economics'!$C$24 -> 731888.64
A11: Total revenue | C11: =SUM(C5:C10) -> 18028.56 | D11: =SUM(D5:D10) -> 217104.87 | E11: =SUM(E5:E10) -> 1084578.1 | F11: =SUM(F5:F10) -> 3547798 | G11: =SUM(G5:G10) -> 9061606.7
A12: Growth | C12: =0 -> 0 | D12: =IF(C11=0,0,D11/C11-1) -> 11.042275 | E12: =IF(D11=0,0,E11/D11-1) -> 3.9956416 | F12: =IF(E11=0,0,F11/E11-1) -> 2.2711318 | G12: =IF(F11=0,0,G11/F11-1) -> 1.5541496
A14: Revenue mix
A15: Featured spots | C15: =IF(C$11=0,0,C5/C$11) -> 0.32577643 | D15: =IF(D$11=0,0,D5/D$11) -> 0.26565783 | E15: =IF(E$11=0,0,E5/E$11) -> 0.23166512 | F15: =IF(F$11=0,0,F5/F$11) -> 0.21228448 | G15: =IF(G$11=0,0,G5/G$11) -> 0.20006056
A16: Enhanced listings | C16: =IF(C$11=0,0,C6/C$11) -> 0.3364262 | D16: =IF(D$11=0,0,D6/D$11) -> 0.31499077 | E16: =IF(E$11=0,0,E6/E$11) -> 0.2983489 | F16: =IF(F$11=0,0,F6/F$11) -> 0.29016016 | G16: =IF(G$11=0,0,G6/G$11) -> 0.28648346
A17: Category sponsorships | C17: =IF(C$11=0,0,C7/C$11) -> 0 | D17: =IF(D$11=0,0,D7/D$11) -> 0.059447915 | E17: =IF(E$11=0,0,E7/E$11) -> 0.076736314 | F17: =IF(F$11=0,0,F7/F$11) -> 0.086108786 | G17: =IF(G$11=0,0,G7/G$11) -> 0.092271043
A18: Newsletter | C18: =IF(C$11=0,0,C8/C$11) -> 0.10483366 | D18: =IF(D$11=0,0,D8/D$11) -> 0.16993078 | E18: =IF(E$11=0,0,E8/E$11) -> 0.18520491 | F18: =IF(F$11=0,0,F8/F$11) -> 0.19375201 | G18: =IF(G$11=0,0,G8/G$11) -> 0.19969545
A19: Banners | C19: =IF(C$11=0,0,C9/C$11) -> 0.2329637 | D19: =IF(D$11=0,0,D9/D$11) -> 0.1899727 | E19: =IF(E$11=0,0,E9/E$11) -> 0.16566441 | F19: =IF(F$11=0,0,F9/F$11) -> 0.15091502 | G19: =IF(G$11=0,0,G9/G$11) -> 0.1407214
A20: Programmatic | C20: =IF(C$11=0,0,C10/C$11) -> 0 | D20: =IF(D$11=0,0,D10/D$11) -> 0 | E20: =IF(E$11=0,0,E10/E$11) -> 0.042380349 | F20: =IF(F$11=0,0,F10/F$11) -> 0.066779541 | G20: =IF(G$11=0,0,G10/G$11) -> 0.080768087

Sheet Headcount
A1: Headcount and people costs
A2: Town-driven roles scale with average live towns; fixed roles come from Assumptions.
A4: Fiscal year | C4: 2027 | D4: 2028 | E4: 2029 | F4: 2030 | G4: 2031
A5: Heads (year end)
A6: Leadership | C6: =Assumptions!C$85 -> 2 | D6: =Assumptions!D$85 -> 2 | E6: =Assumptions!E$85 -> 3 | F6: =Assumptions!F$85 -> 4 | G6: =Assumptions!G$85 -> 5
A7: Engineering and product | C7: =Assumptions!C$86 -> 3 | D7: =Assumptions!D$86 -> 5 | E7: =Assumptions!E$86 -> 8 | F7: =Assumptions!F$86 -> 11 | G7: =Assumptions!G$86 -> 14
A8: Finance, legal and operations | C8: =Assumptions!C$87 -> 1 | D8: =Assumptions!D$87 -> 1 | E8: =Assumptions!E$87 -> 2 | F8: =Assumptions!F$87 -> 3 | G8: =Assumptions!G$87 -> 4
A9: Editorial reviewers | C9: =IF(Rollout!C$7=0,0,MAX(1,ROUNDUP(Rollout!C$7/Assumptions!$C$71,0))) -> 1 | D9: =IF(Rollout!D$7=0,0,MAX(1,ROUNDUP(Rollout!D$7/Assumptions!$C$71,0))) -> 3 | E9: =IF(Rollout!E$7=0,0,MAX(1,ROUNDUP(Rollout!E$7/Assumptions!$C$71,0))) -> 8 | F9: =IF(Rollout!F$7=0,0,MAX(1,ROUNDUP(Rollout!F$7/Assumptions!$C$71,0))) -> 18 | G9: =IF(Rollout!G$7=0,0,MAX(1,ROUNDUP(Rollout!G$7/Assumptions!$C$71,0))) -> 35
A10: Account executives | C10: =IF(Rollout!C$7=0,0,MAX(1,ROUNDUP(Rollout!C$7/Assumptions!$C$72,0))) -> 1 | D10: =IF(Rollout!D$7=0,0,MAX(1,ROUNDUP(Rollout!D$7/Assumptions!$C$72,0))) -> 4 | E10: =IF(Rollout!E$7=0,0,MAX(1,ROUNDUP(Rollout!E$7/Assumptions!$C$72,0))) -> 10 | F10: =IF(Rollout!F$7=0,0,MAX(1,ROUNDUP(Rollout!F$7/Assumptions!$C$72,0))) -> 23 | G10: =IF(Rollout!G$7=0,0,MAX(1,ROUNDUP(Rollout!G$7/Assumptions!$C$72,0))) -> 46
A11: Support and success | C11: =IF(Rollout!C$7=0,0,MAX(1,ROUNDUP(Rollout!C$7/Assumptions!$C$73,0))) -> 1 | D11: =IF(Rollout!D$7=0,0,MAX(1,ROUNDUP(Rollout!D$7/Assumptions!$C$73,0))) -> 1 | E11: =IF(Rollout!E$7=0,0,MAX(1,ROUNDUP(Rollout!E$7/Assumptions!$C$73,0))) -> 3 | F11: =IF(Rollout!F$7=0,0,MAX(1,ROUNDUP(Rollout!F$7/Assumptions!$C$73,0))) -> 6 | G11: =IF(Rollout!G$7=0,0,MAX(1,ROUNDUP(Rollout!G$7/Assumptions!$C$73,0))) -> 12
A12: Total heads | C12: =SUM(C6:C11) -> 9 | D12: =SUM(D6:D11) -> 16 | E12: =SUM(E6:E11) -> 34 | F12: =SUM(F6:F11) -> 65 | G12: =SUM(G6:G11) -> 116
A13: New hires | C13: =C12 -> 9 | D13: =MAX(0,D12-C12) -> 7 | E13: =MAX(0,E12-D12) -> 18 | F13: =MAX(0,F12-E12) -> 31 | G13: =MAX(0,G12-F12) -> 51
A15: Fully loaded cost ($, average heads in year)
A16: Leadership | C16: =C6*0.75*Assumptions!$C$76*(1+Assumptions!$C$68)*(1+Assumptions!$C$69)^0 -> 300000 | D16: =(C6+D6)/2*Assumptions!$C$76*(1+Assumptions!$C$68)*(1+Assumptions!$C$69)^1 -> 412000 | E16: =(D6+E6)/2*Assumptions!$C$76*(1+Assumptions!$C$68)*(1+Assumptions!$C$69)^2 -> 530450 | F16: =(E6+F6)/2*Assumptions!$C$76*(1+Assumptions!$C$68)*(1+Assumptions!$C$69)^3 -> 764908.9 | G16: =(F6+G6)/2*Assumptions!$C$76*(1+Assumptions!$C$68)*(1+Assumptions!$C$69)^4 -> 1012957.9
A17: Engineering and product | C17: =C7*0.75*Assumptions!$C$77*(1+Assumptions!$C$68)*(1+Assumptions!$C$69)^0 -> 478125 | D17: =(C7+D7)/2*Assumptions!$C$77*(1+Assumptions!$C$68)*(1+Assumptions!$C$69)^1 -> 875500 | E17: =(D7+E7)/2*Assumptions!$C$77*(1+Assumptions!$C$68)*(1+Assumptions!$C$69)^2 -> 1465368.1 | F17: =(E7+F7)/2*Assumptions!$C$77*(1+Assumptions!$C$68)*(1+Assumptions!$C$69)^3 -> 2205942.6 | G17: =(F7+G7)/2*Assumptions!$C$77*(1+Assumptions!$C$68)*(1+Assumptions!$C$69)^4 -> 2989632.8
A18: Finance, legal and operations | C18: =C8*0.75*Assumptions!$C$81*(1+Assumptions!$C$68)*(1+Assumptions!$C$69)^0 -> 103125 | D18: =(C8+D8)/2*Assumptions!$C$81*(1+Assumptions!$C$68)*(1+Assumptions!$C$69)^1 -> 141625 | E18: =(D8+E8)/2*Assumptions!$C$81*(1+Assumptions!$C$68)*(1+Assumptions!$C$69)^2 -> 218810.62 | F18: =(E8+F8)/2*Assumptions!$C$81*(1+Assumptions!$C$68)*(1+Assumptions!$C$69)^3 -> 375624.91 | G18: =(F8+G8)/2*Assumptions!$C$81*(1+Assumptions!$C$68)*(1+Assumptions!$C$69)^4 -> 541651.11
A19: Editorial reviewers | C19: =C9*0.75*Assumptions!$C$78*(1+Assumptions!$C$68)*(1+Assumptions!$C$69)^0 -> 65625 | D19: =(C9+D9)/2*Assumptions!$C$78*(1+Assumptions!$C$68)*(1+Assumptions!$C$69)^1 -> 180250 | E19: =(D9+E9)/2*Assumptions!$C$78*(1+Assumptions!$C$68)*(1+Assumptions!$C$69)^2 -> 510558.12 | F19: =(E9+F9)/2*Assumptions!$C$78*(1+Assumptions!$C$68)*(1+Assumptions!$C$69)^3 -> 1242977 | G19: =(F9+G9)/2*Assumptions!$C$78*(1+Assumptions!$C$68)*(1+Assumptions!$C$69)^4 -> 2609773.6
A20: Account executives | C20: =C10*0.75*Assumptions!$C$79*(1+Assumptions!$C$68)*(1+Assumptions!$C$69)^0 -> 60937.5 | D20: =(C10+D10)/2*Assumptions!$C$79*(1+Assumptions!$C$68)*(1+Assumptions!$C$69)^1 -> 209218.75 | E20: =(D10+E10)/2*Assumptions!$C$79*(1+Assumptions!$C$68)*(1+Assumptions!$C$69)^2 -> 603386.88 | F20: =(E10+F10)/2*Assumptions!$C$79*(1+Assumptions!$C$68)*(1+Assumptions!$C$69)^3 -> 1464937.1 | G20: =(F10+G10)/2*Assumptions!$C$79*(1+Assumptions!$C$68)*(1+Assumptions!$C$69)^4 -> 3154941.9
A21: Support and success | C21: =C11*0.75*Assumptions!$C$80*(1+Assumptions!$C$68)*(1+Assumptions!$C$69)^0 -> 51562.5 | D21: =(C11+D11)/2*Assumptions!$C$80*(1+Assumptions!$C$68)*(1+Assumptions!$C$69)^1 -> 70812.5 | E21: =(D11+E11)/2*Assumptions!$C$80*(1+Assumptions!$C$68)*(1+Assumptions!$C$69)^2 -> 145873.75 | F21: =(E11+F11)/2*Assumptions!$C$80*(1+Assumptions!$C$68)*(1+Assumptions!$C$69)^3 -> 338062.42 | G21: =(F11+G11)/2*Assumptions!$C$80*(1+Assumptions!$C$68)*(1+Assumptions!$C$69)^4 -> 696408.58
A22: Total people cost | C22: =SUM(C16:C21) -> 1059375 | D22: =SUM(D16:D21) -> 1889406.2 | E22: =SUM(E16:E21) -> 3474447.5 | F22: =SUM(F16:F21) -> 6392453 | G22: =SUM(G16:G21) -> 11005366
A24: FY2027 uses 75% of year-end heads (team builds through the year); later years use the average of opening and closing heads.

Sheet Costs
A1: Costs ($)
A2: Direct costs from cohorts; operating costs from Headcount and Assumptions.
A4: Fiscal year | C4: 2027 | D4: 2028 | E4: 2029 | F4: 2030 | G4: 2031
A5: Cost of revenue
A6: AI (writing and fact-checking) | C6: =Rollout!$C$5*'Unit Economics'!$C$29 -> 4058.8 | D6: =Rollout!$C$5*'Unit Economics'!$D$29+Rollout!$D$5*'Unit Economics'!$C$29 -> 24109.272 | E6: =Rollout!$C$5*'Unit Economics'!$E$29+Rollout!$D$5*'Unit Economics'!$D$29+Rollout!$E$5*'Unit Economics'!$C$29 -> 79796.008 | F6: =Rollout!$C$5*'Unit Economics'!$F$29+Rollout!$D$5*'Unit Economics'!$E$29+Rollout!$E$5*'Unit Economics'!$D$29+Rollout!$F$5*'Unit Economics'!$C$29 -> 198394.14 | G6: =Rollout!$C$5*'Unit Economics'!$G$29+Rollout!$D$5*'Unit Economics'!$F$29+Rollout!$E$5*'Unit Economics'!$E$29+Rollout!$F$5*'Unit Economics'!$D$29+Rollout!$G$5*'Unit Economics'!$C$29 -> 414728.18
A7: Hosting, database and data | C7: =Rollout!$C$5*'Unit Economics'!$C$30 -> 3000 | D7: =Rollout!$C$5*'Unit Economics'!$D$30+Rollout!$D$5*'Unit Economics'!$C$30 -> 17820 | E7: =Rollout!$C$5*'Unit Economics'!$E$30+Rollout!$D$5*'Unit Economics'!$D$30+Rollout!$E$5*'Unit Economics'!$C$30 -> 58980 | F7: =Rollout!$C$5*'Unit Economics'!$F$30+Rollout!$D$5*'Unit Economics'!$E$30+Rollout!$E$5*'Unit Economics'!$D$30+Rollout!$F$5*'Unit Economics'!$C$30 -> 146640 | G7: =Rollout!$C$5*'Unit Economics'!$G$30+Rollout!$D$5*'Unit Economics'!$F$30+Rollout!$E$5*'Unit Economics'!$E$30+Rollout!$F$5*'Unit Economics'!$D$30+Rollout!$G$5*'Unit Economics'!$C$30 -> 306540
A8: Email sending | C8: =Rollout!$C$5*'Unit Economics'!$C$31 -> 63 | D8: =Rollout!$C$5*'Unit Economics'!$D$31+Rollout!$D$5*'Unit Economics'!$C$31 -> 577.92 | E8: =Rollout!$C$5*'Unit Economics'!$E$31+Rollout!$D$5*'Unit Economics'!$D$31+Rollout!$E$5*'Unit Economics'!$C$31 -> 2412.48 | F8: =Rollout!$C$5*'Unit Economics'!$F$31+Rollout!$D$5*'Unit Economics'!$E$31+Rollout!$E$5*'Unit Economics'!$D$31+Rollout!$F$5*'Unit Economics'!$C$31 -> 7026.6 | G8: =Rollout!$C$5*'Unit Economics'!$G$31+Rollout!$D$5*'Unit Economics'!$F$31+Rollout!$E$5*'Unit Economics'!$E$31+Rollout!$F$5*'Unit Economics'!$D$31+Rollout!$G$5*'Unit Economics'!$C$31 -> 16544.22
A9: Card processing | C9: =Rollout!$C$5*'Unit Economics'!$C$32 -> 544.07424 | D9: =Rollout!$C$5*'Unit Economics'!$D$32+Rollout!$D$5*'Unit Economics'!$C$32 -> 5666.618 | E9: =Rollout!$C$5*'Unit Economics'!$E$32+Rollout!$D$5*'Unit Economics'!$D$32+Rollout!$E$5*'Unit Economics'!$C$32 -> 25627.84 | F9: =Rollout!$C$5*'Unit Economics'!$F$32+Rollout!$D$5*'Unit Economics'!$E$32+Rollout!$E$5*'Unit Economics'!$D$32+Rollout!$F$5*'Unit Economics'!$C$32 -> 79001.959 | G9: =Rollout!$C$5*'Unit Economics'!$G$32+Rollout!$D$5*'Unit Economics'!$F$32+Rollout!$E$5*'Unit Economics'!$E$32+Rollout!$F$5*'Unit Economics'!$D$32+Rollout!$G$5*'Unit Economics'!$C$32 -> 194496.48
A10: Domains (renewals and new) | C10: =Rollout!$C$5*'Unit Economics'!$C$33+Rollout!C5*Assumptions!$C$62*Assumptions!$F$10 -> 300 | D10: =Rollout!$C$5*'Unit Economics'!$D$33+Rollout!$D$5*'Unit Economics'!$C$33+Rollout!D5*Assumptions!$C$62*Assumptions!$F$10 -> 1588 | E10: =Rollout!$C$5*'Unit Economics'!$E$33+Rollout!$D$5*'Unit Economics'!$D$33+Rollout!$E$5*'Unit Economics'!$C$33+Rollout!E5*Assumptions!$C$62*Assumptions!$F$10 -> 4932 | F10: =Rollout!$C$5*'Unit Economics'!$F$33+Rollout!$D$5*'Unit Economics'!$E$33+Rollout!$E$5*'Unit Economics'!$D$33+Rollout!$F$5*'Unit Economics'!$C$33+Rollout!F5*Assumptions!$C$62*Assumptions!$F$10 -> 11776 | G10: =Rollout!$C$5*'Unit Economics'!$G$33+Rollout!$D$5*'Unit Economics'!$F$33+Rollout!$E$5*'Unit Economics'!$E$33+Rollout!$F$5*'Unit Economics'!$D$33+Rollout!$G$5*'Unit Economics'!$C$33+Rollout!G5*Assumptions!$C$62*Assumptions!$F$10 -> 23936
A11: Total cost of revenue | C11: =SUM(C6:C10) -> 7965.8742 | D11: =SUM(D6:D10) -> 49761.81 | E11: =SUM(E6:E10) -> 171748.33 | F11: =SUM(F6:F10) -> 442838.7 | G11: =SUM(G6:G10) -> 956244.88
A13: Operating expenses
A14: Editorial review (people) | C14: =Headcount!C19 -> 65625 | D14: =Headcount!D19 -> 180250 | E14: =Headcount!E19 -> 510558.12 | F14: =Headcount!F19 -> 1242977 | G14: =Headcount!G19 -> 2609773.6
A15: Sales (people) | C15: =Headcount!C20 -> 60937.5 | D15: =Headcount!D20 -> 209218.75 | E15: =Headcount!E20 -> 603386.88 | F15: =Headcount!F20 -> 1464937.1 | G15: =Headcount!G20 -> 3154941.9
A16: Sales commission | C16: =(Rollout!$C$5*'Unit Economics'!$C$27)*Assumptions!$C$70 -> 609 | D16: =(Rollout!$C$5*'Unit Economics'!$D$27+Rollout!$D$5*'Unit Economics'!$C$27)*Assumptions!$C$70 -> 9104.3232 | E16: =(Rollout!$C$5*'Unit Economics'!$E$27+Rollout!$D$5*'Unit Economics'!$D$27+Rollout!$E$5*'Unit Economics'!$C$27)*Assumptions!$C$70 -> 46377.173 | F16: =(Rollout!$C$5*'Unit Economics'!$F$27+Rollout!$D$5*'Unit Economics'!$E$27+Rollout!$E$5*'Unit Economics'!$D$27+Rollout!$F$5*'Unit Economics'!$C$27)*Assumptions!$C$70 -> 152830.56 | G16: =(Rollout!$C$5*'Unit Economics'!$G$27+Rollout!$D$5*'Unit Economics'!$F$27+Rollout!$E$5*'Unit Economics'!$E$27+Rollout!$F$5*'Unit Economics'!$D$27+Rollout!$G$5*'Unit Economics'!$C$27)*Assumptions!$C$70 -> 392084.75
A17: Support and success (people) | C17: =Headcount!C21 -> 51562.5 | D17: =Headcount!D21 -> 70812.5 | E17: =Headcount!E21 -> 145873.75 | F17: =Headcount!F21 -> 338062.42 | G17: =Headcount!G21 -> 696408.58
A18: Launch marketing and launch AI | C18: =Rollout!C5*(Assumptions!$C$63+Assumptions!$C$61)*Assumptions!$F$10 -> 30500 | D18: =Rollout!D5*(Assumptions!$C$63+Assumptions!$C$61)*Assumptions!$F$10 -> 122000 | E18: =Rollout!E5*(Assumptions!$C$63+Assumptions!$C$61)*Assumptions!$F$10 -> 305000 | F18: =Rollout!F5*(Assumptions!$C$63+Assumptions!$C$61)*Assumptions!$F$10 -> 610000 | G18: =Rollout!G5*(Assumptions!$C$63+Assumptions!$C$61)*Assumptions!$F$10 -> 1067500
A19: Paid subscriber acquisition | C19: =Rollout!$C$5*'Unit Economics'!$C$41 -> 3360 | D19: =Rollout!$C$5*'Unit Economics'!$D$41+Rollout!$D$5*'Unit Economics'!$C$41 -> 18771.2 | E19: =Rollout!$C$5*'Unit Economics'!$E$41+Rollout!$D$5*'Unit Economics'!$D$41+Rollout!$E$5*'Unit Economics'!$C$41 -> 59001.6 | F19: =Rollout!$C$5*'Unit Economics'!$F$41+Rollout!$D$5*'Unit Economics'!$E$41+Rollout!$E$5*'Unit Economics'!$D$41+Rollout!$F$5*'Unit Economics'!$C$41 -> 139843.2 | G19: =Rollout!$C$5*'Unit Economics'!$G$41+Rollout!$D$5*'Unit Economics'!$F$41+Rollout!$E$5*'Unit Economics'!$E$41+Rollout!$F$5*'Unit Economics'!$D$41+Rollout!$G$5*'Unit Economics'!$C$41 -> 279003.2
A20: Corporate marketing | C20: =Assumptions!C$91 -> 50000 | D20: =Assumptions!D$91 -> 150000 | E20: =Assumptions!E$91 -> 300000 | F20: =Assumptions!F$91 -> 500000 | G20: =Assumptions!G$91 -> 700000
A21: Engineering and product (people) | C21: =Headcount!C17 -> 478125 | D21: =Headcount!D17 -> 875500 | E21: =Headcount!E17 -> 1465368.1 | F21: =Headcount!F17 -> 2205942.6 | G21: =Headcount!G17 -> 2989632.8
A22: Leadership (people) | C22: =Headcount!C16 -> 300000 | D22: =Headcount!D16 -> 412000 | E22: =Headcount!E16 -> 530450 | F22: =Headcount!F16 -> 764908.9 | G22: =Headcount!G16 -> 1012957.9
A23: Finance, legal and operations (people) | C23: =Headcount!C18 -> 103125 | D23: =Headcount!D18 -> 141625 | E23: =Headcount!E18 -> 218810.62 | F23: =Headcount!F18 -> 375624.91 | G23: =Headcount!G18 -> 541651.11
A24: Legal and media liability insurance | C24: =Assumptions!C$92+Rollout!C8*Assumptions!$C$93 -> 61000 | D24: =Assumptions!D$92+Rollout!D8*Assumptions!$C$93 -> 95970 | E24: =Assumptions!E$92+Rollout!E8*Assumptions!$C$93 -> 159800 | F24: =Assumptions!F$92+Rollout!F8*Assumptions!$C$93 -> 249270 | G24: =Assumptions!G$92+Rollout!G8*Assumptions!$C$93 -> 363030
A25: Software and tools | C25: =Headcount!C12*Assumptions!$C$94 -> 27000 | D25: =Headcount!D12*Assumptions!$C$94 -> 48000 | E25: =Headcount!E12*Assumptions!$C$94 -> 102000 | F25: =Headcount!F12*Assumptions!$C$94 -> 195000 | G25: =Headcount!G12*Assumptions!$C$94 -> 348000
A26: Total operating expenses | C26: =SUM(C14:C25) -> 1231844 | D26: =SUM(D14:D25) -> 2333251.8 | E26: =SUM(E14:E25) -> 4446626.3 | F26: =SUM(F14:F25) -> 8239396.7 | G26: =SUM(G14:G25) -> 14154984

Sheet P&L
A1: Income statement ($)
A2: Fiscal years 2027-2031.
A4: Fiscal year | C4: 2027 | D4: 2028 | E4: 2029 | F4: 2030 | G4: 2031
A5: Revenue | C5: =Revenue!C11 -> 18028.56 | D5: =Revenue!D11 -> 217104.87 | E5: =Revenue!E11 -> 1084578.1 | F5: =Revenue!F11 -> 3547798 | G5: =Revenue!G11 -> 9061606.7
A6: Cost of revenue | C6: =Costs!C11 -> 7965.8742 | D6: =Costs!D11 -> 49761.81 | E6: =Costs!E11 -> 171748.33 | F6: =Costs!F11 -> 442838.7 | G6: =Costs!G11 -> 956244.88
A7: Gross profit | C7: =C5-C6 -> 10062.686 | D7: =D5-D6 -> 167343.06 | E7: =E5-E6 -> 912829.81 | F7: =F5-F6 -> 3104959.3 | G7: =G5-G6 -> 8105361.9
A8: Gross margin | C8: =IF(C5=0,0,C7/C5) -> 0.5581525 | D8: =IF(D5=0,0,D7/D5) -> 0.77079368 | E8: =IF(E5=0,0,E7/E5) -> 0.84164504 | F8: =IF(F5=0,0,F7/F5) -> 0.87517928 | G8: =IF(G5=0,0,G7/G5) -> 0.89447292
A10: Editorial | C10: =Costs!C14 -> 65625 | D10: =Costs!D14 -> 180250 | E10: =Costs!E14 -> 510558.12 | F10: =Costs!F14 -> 1242977 | G10: =Costs!G14 -> 2609773.6
A11: Sales and marketing | C11: =Costs!C15+Costs!C16+Costs!C17+Costs!C18+Costs!C19+Costs!C20 -> 196969 | D11: =Costs!D15+Costs!D16+Costs!D17+Costs!D18+Costs!D19+Costs!D20 -> 579906.77 | E11: =Costs!E15+Costs!E16+Costs!E17+Costs!E18+Costs!E19+Costs!E20 -> 1459639.4 | F11: =Costs!F15+Costs!F16+Costs!F17+Costs!F18+Costs!F19+Costs!F20 -> 3205673.3 | G11: =Costs!G15+Costs!G16+Costs!G17+Costs!G18+Costs!G19+Costs!G20 -> 6289938.4
A12: Engineering and product | C12: =Costs!C21 -> 478125 | D12: =Costs!D21 -> 875500 | E12: =Costs!E21 -> 1465368.1 | F12: =Costs!F21 -> 2205942.6 | G12: =Costs!G21 -> 2989632.8
A13: General and administrative | C13: =Costs!C22+Costs!C23+Costs!C24+Costs!C25 -> 491125 | D13: =Costs!D22+Costs!D23+Costs!D24+Costs!D25 -> 697595 | E13: =Costs!E22+Costs!E23+Costs!E24+Costs!E25 -> 1011060.6 | F13: =Costs!F22+Costs!F23+Costs!F24+Costs!F25 -> 1584803.8 | G13: =Costs!G22+Costs!G23+Costs!G24+Costs!G25 -> 2265639
A14: Total operating expenses | C14: =SUM(C10:C13) -> 1231844 | D14: =SUM(D10:D13) -> 2333251.8 | E14: =SUM(E10:E13) -> 4446626.3 | F14: =SUM(F10:F13) -> 8239396.7 | G14: =SUM(G10:G13) -> 14154984
A16: EBITDA | C16: =C7-C14 -> -1221781.3 | D16: =D7-D14 -> -2165908.7 | E16: =E7-E14 -> -3533796.5 | F16: =F7-F14 -> -5134437.4 | G16: =G7-G14 -> -6049621.9
A17: EBITDA margin | C17: =IF(C5=0,0,C16/C5) -> -67.769213 | D17: =IF(D5=0,0,D16/D5) -> -9.9763247 | E17: =IF(E5=0,0,E16/E5) -> -3.2582221 | F17: =IF(F5=0,0,F16/F5) -> -1.4472181 | G17: =IF(G5=0,0,G16/G5) -> -0.66761029
A18: Capital expenditure (memo) | C18: =Headcount!C13*Assumptions!$C$95 -> 22500 | D18: =Headcount!D13*Assumptions!$C$95 -> 17500 | E18: =Headcount!E13*Assumptions!$C$95 -> 45000 | F18: =Headcount!F13*Assumptions!$C$95 -> 77500 | G18: =Headcount!G13*Assumptions!$C$95 -> 127500
A19: Depreciation | C19: =(C18)/Assumptions!$C$96 -> 7500 | D19: =(C18+D18)/Assumptions!$C$96 -> 13333.333 | E19: =(C18+D18+E18)/Assumptions!$C$96 -> 28333.333 | F19: =(D18+E18+F18)/Assumptions!$C$96 -> 46666.667 | G19: =(E18+F18+G18)/Assumptions!$C$96 -> 83333.333
A20: Operating income (EBIT) | C20: =C16-C19 -> -1229281.3 | D20: =D16-D19 -> -2179242 | E20: =E16-E19 -> -3562129.8 | F20: =F16-F19 -> -5181104.1 | G20: =G16-G19 -> -6132955.3
A21: Tax losses available, opening | C21: =0 -> 0 | D21: =C23 -> 1229281.3 | E21: =D23 -> 3408523.4 | F21: =E23 -> 6970653.2 | G21: =F23 -> 12151757
A22: Taxable income after losses used | C22: =MAX(0,C20-C21) -> 0 | D22: =MAX(0,D20-D21) -> 0 | E22: =MAX(0,E20-E21) -> 0 | F22: =MAX(0,F20-F21) -> 0 | G22: =MAX(0,G20-G21) -> 0
A23: Tax losses available, closing | C23: =MAX(0,C21-MAX(0,C20))+MAX(0,-C20) -> 1229281.3 | D23: =MAX(0,D21-MAX(0,D20))+MAX(0,-D20) -> 3408523.4 | E23: =MAX(0,E21-MAX(0,E20))+MAX(0,-E20) -> 6970653.2 | F23: =MAX(0,F21-MAX(0,F20))+MAX(0,-F20) -> 12151757 | G23: =MAX(0,G21-MAX(0,G20))+MAX(0,-G20) -> 18284713
A24: Income tax | C24: =C22*Assumptions!$C$99 -> 0 | D24: =D22*Assumptions!$C$99 -> 0 | E24: =E22*Assumptions!$C$99 -> 0 | F24: =F22*Assumptions!$C$99 -> 0 | G24: =G22*Assumptions!$C$99 -> 0
A25: Net income | C25: =C20-C24 -> -1229281.3 | D25: =D20-D24 -> -2179242 | E25: =E20-E24 -> -3562129.8 | F25: =F20-F24 -> -5181104.1 | G25: =G20-G24 -> -6132955.3

Sheet Cash Flow
A1: Cash flow and funding ($)
A2: Simplified: EBITDA less tax, capex and working capital, plus equity raised.
A4: Fiscal year | C4: 2027 | D4: 2028 | E4: 2029 | F4: 2030 | G4: 2031
A5: EBITDA | C5: ='P&L'!C16 -> -1221781.3 | D5: ='P&L'!D16 -> -2165908.7 | E5: ='P&L'!E16 -> -3533796.5 | F5: ='P&L'!F16 -> -5134437.4 | G5: ='P&L'!G16 -> -6049621.9
A6: Income tax paid | C6: =-'P&L'!C24 -> 0 | D6: =-'P&L'!D24 -> 0 | E6: =-'P&L'!E24 -> 0 | F6: =-'P&L'!F24 -> 0 | G6: =-'P&L'!G24 -> 0
A7: Capital expenditure | C7: =-'P&L'!C18 -> -22500 | D7: =-'P&L'!D18 -> -17500 | E7: =-'P&L'!E18 -> -45000 | F7: =-'P&L'!F18 -> -77500 | G7: =-'P&L'!G18 -> -127500
A8: Increase in net working capital | C8: =-'P&L'!C5*Assumptions!$C$100 -> -540.8568 | D8: =-('P&L'!D5-'P&L'!C5)*Assumptions!$C$100 -> -5972.2894 | E8: =-('P&L'!E5-'P&L'!D5)*Assumptions!$C$100 -> -26024.198 | F8: =-('P&L'!F5-'P&L'!E5)*Assumptions!$C$100 -> -73896.596 | G8: =-('P&L'!G5-'P&L'!F5)*Assumptions!$C$100 -> -165414.26
A9: Free cash flow | C9: =SUM(C5:C8) -> -1244822.2 | D9: =SUM(D5:D8) -> -2189381 | E9: =SUM(E5:E8) -> -3604820.7 | F9: =SUM(F5:F8) -> -5285834 | G9: =SUM(G5:G8) -> -6342536.2
A10: Equity raised | C10: =Assumptions!C$104 -> 2000000 | D10: =Assumptions!D$104 -> 8000000 | E10: =Assumptions!E$104 -> 0 | F10: =Assumptions!F$104 -> 15000000 | G10: =Assumptions!G$104 -> 0
A11: Net change in cash | C11: =C9+C10 -> 755177.83 | D11: =D9+D10 -> 5810619 | E11: =E9+E10 -> -3604820.7 | F11: =F9+F10 -> 9714166 | G11: =G9+G10 -> -6342536.2
A12: Opening cash | C12: =Assumptions!$C$101 -> 250000 | D12: =C13 -> 1005177.8 | E12: =D13 -> 6815796.8 | F12: =E13 -> 3210976.2 | G12: =F13 -> 12925142
A13: Closing cash | C13: =C12+C11 -> 1005177.8 | D13: =D12+D11 -> 6815796.8 | E13: =E12+E11 -> 3210976.2 | F13: =F12+F11 -> 12925142 | G13: =G12+G11 -> 6582606
A14: Cash below zero? (1 = yes: raise more or cut) | C14: =IF(C13<0,1,0) -> 0 | D14: =IF(D13<0,1,0) -> 0 | E14: =IF(E13<0,1,0) -> 0 | F14: =IF(F13<0,1,0) -> 0 | G14: =IF(G13<0,1,0) -> 0
A16: Lowest closing cash, FY2027-FY2031 | C16: =MIN(C13:G13) -> 1005177.8
A17: Cumulative free cash flow before turning positive (funding need) | C17: =-MIN(0,C9,C9+D9,C9+D9+E9,C9+D9+E9+F9,C9+D9+E9+F9+G9) -> 18667394 | H17: Deepest point of cumulative free cash flow: the equity the plan needs, before any buffer.

Sheet KPIs
A1: Key metrics
A2: Operating and financial KPIs, all formulas.
A4: Fiscal year | C4: 2027 | D4: 2028 | E4: 2029 | F4: 2030 | G4: 2031
A5: Footprint and audience
A6: Towns launched in year | C6: =Rollout!C5 -> 20 | D6: =Rollout!D5 -> 80 | E6: =Rollout!E5 -> 200 | F6: =Rollout!F5 -> 400 | G6: =Rollout!G5 -> 700
A7: Live towns at year end | C7: =Rollout!C7 -> 20 | D7: =Rollout!D7 -> 99.4 | E7: =Rollout!E7 -> 296.6 | F7: =Rollout!F7 -> 688.8 | G7: =Rollout!G7 -> 1371.8
A8: Newsletter subscribers (year end) | C8: =Rollout!$C$5*'Unit Economics'!$C$10 -> 4200 | D8: =Rollout!$C$5*'Unit Economics'!$D$10+Rollout!$D$5*'Unit Economics'!$C$10 -> 27664 | E8: =Rollout!$C$5*'Unit Economics'!$E$10+Rollout!$D$5*'Unit Economics'!$D$10+Rollout!$E$5*'Unit Economics'!$C$10 -> 101416 | F8: =Rollout!$C$5*'Unit Economics'!$F$10+Rollout!$D$5*'Unit Economics'!$E$10+Rollout!$E$5*'Unit Economics'!$D$10+Rollout!$F$5*'Unit Economics'!$C$10 -> 276220 | G8: =Rollout!$C$5*'Unit Economics'!$G$10+Rollout!$D$5*'Unit Economics'!$F$10+Rollout!$E$5*'Unit Economics'!$E$10+Rollout!$F$5*'Unit Economics'!$D$10+Rollout!$G$5*'Unit Economics'!$C$10 -> 624974
A9: Pageviews in year | C9: =Rollout!$C$5*'Unit Economics'!$C$12 -> 1680000 | D9: =Rollout!$C$5*'Unit Economics'!$D$12+Rollout!$D$5*'Unit Economics'!$C$12 -> 13238400 | E9: =Rollout!$C$5*'Unit Economics'!$E$12+Rollout!$D$5*'Unit Economics'!$D$12+Rollout!$E$5*'Unit Economics'!$C$12 -> 52449600 | F9: =Rollout!$C$5*'Unit Economics'!$F$12+Rollout!$D$5*'Unit Economics'!$E$12+Rollout!$E$5*'Unit Economics'!$D$12+Rollout!$F$5*'Unit Economics'!$C$12 -> 148142400 | G9: =Rollout!$C$5*'Unit Economics'!$G$12+Rollout!$D$5*'Unit Economics'!$F$12+Rollout!$E$5*'Unit Economics'!$E$12+Rollout!$F$5*'Unit Economics'!$D$12+Rollout!$G$5*'Unit Economics'!$C$12 -> 341644800
A10: Customers
A11: Paid directory products (average in year) | C11: =Rollout!$C$5*'Unit Economics'!$C$17 -> 109.92 | D11: =Rollout!$C$5*'Unit Economics'!$D$17+Rollout!$D$5*'Unit Economics'!$C$17 -> 789.268 | E11: =Rollout!$C$5*'Unit Economics'!$E$17+Rollout!$D$5*'Unit Economics'!$D$17+Rollout!$E$5*'Unit Economics'!$C$17 -> 3107.832 | F11: =Rollout!$C$5*'Unit Economics'!$F$17+Rollout!$D$5*'Unit Economics'!$E$17+Rollout!$E$5*'Unit Economics'!$D$17+Rollout!$F$5*'Unit Economics'!$C$17 -> 8941.732 | G11: =Rollout!$C$5*'Unit Economics'!$G$17+Rollout!$D$5*'Unit Economics'!$F$17+Rollout!$E$5*'Unit Economics'!$E$17+Rollout!$F$5*'Unit Economics'!$D$17+Rollout!$G$5*'Unit Economics'!$C$17 -> 21138.306
A12: Directory revenue per paid product per month ($) | C12: =IF(C11=0,0,(Revenue!C5+Revenue!C6+Revenue!C7)/C11/12) -> 9.0509461 | D12: =IF(D11=0,0,(Revenue!D5+Revenue!D6+Revenue!D7)/D11/12) -> 14.672675 | E12: =IF(E11=0,0,(Revenue!E5+Revenue!E6+Revenue!E7)/E11/12) -> 17.645423 | F12: =IF(F11=0,0,(Revenue!F5+Revenue!F6+Revenue!F7)/F11/12) -> 19.459957 | G12: =IF(G11=0,0,(Revenue!G5+Revenue!G6+Revenue!G7)/G11/12) -> 20.67729
A13: Financial
A14: Revenue ($) | C14: ='P&L'!C5 -> 18028.56 | D14: ='P&L'!D5 -> 217104.87 | E14: ='P&L'!E5 -> 1084578.1 | F14: ='P&L'!F5 -> 3547798 | G14: ='P&L'!G5 -> 9061606.7
A15: Revenue per average live town ($) | C15: =IF(Rollout!C8=0,0,'P&L'!C5/Rollout!C8) -> 1802.856 | D15: =IF(Rollout!D8=0,0,'P&L'!D5/Rollout!D8) -> 3636.5975 | E15: =IF(Rollout!E8=0,0,'P&L'!E5/Rollout!E8) -> 5477.6673 | F15: =IF(Rollout!F8=0,0,'P&L'!F5/Rollout!F8) -> 7200.7266 | G15: =IF(Rollout!G8=0,0,'P&L'!G5/Rollout!G8) -> 8795.1148
A16: Gross margin | C16: ='P&L'!C8 -> 0.5581525 | D16: ='P&L'!D8 -> 0.77079368 | E16: ='P&L'!E8 -> 0.84164504 | F16: ='P&L'!F8 -> 0.87517928 | G16: ='P&L'!G8 -> 0.89447292
A17: EBITDA ($) | C17: ='P&L'!C16 -> -1221781.3 | D17: ='P&L'!D16 -> -2165908.7 | E17: ='P&L'!E16 -> -3533796.5 | F17: ='P&L'!F16 -> -5134437.4 | G17: ='P&L'!G16 -> -6049621.9
A18: EBITDA margin | C18: ='P&L'!C17 -> -67.769213 | D18: ='P&L'!D17 -> -9.9763247 | E18: ='P&L'!E17 -> -3.2582221 | F18: ='P&L'!F17 -> -1.4472181 | G18: ='P&L'!G17 -> -0.66761029
A19: Closing cash ($) | C19: ='Cash Flow'!C13 -> 1005177.8 | D19: ='Cash Flow'!D13 -> 6815796.8 | E19: ='Cash Flow'!E13 -> 3210976.2 | F19: ='Cash Flow'!F13 -> 12925142 | G19: ='Cash Flow'!G13 -> 6582606
A20: AI cost as % of revenue | C20: =IF('P&L'!C5=0,0,Costs!C6/'P&L'!C5) -> 0.22513168 | D20: =IF('P&L'!D5=0,0,Costs!D6/'P&L'!D5) -> 0.11104897 | E20: =IF('P&L'!E5=0,0,Costs!E6/'P&L'!E5) -> 0.073573314 | F20: =IF('P&L'!F5=0,0,Costs!F6/'P&L'!F5) -> 0.055920361 | G20: =IF('P&L'!G5=0,0,Costs!G6/'P&L'!G5) -> 0.045767621 | H20: CLAUDE.md §8 asks for an alert when AI cost per article jumps; this tracks the overall share.
A21: Central costs (engineering, leadership, G&A, brand, fixed legal, tools) ($) | C21: =Costs!C21+Costs!C22+Costs!C23+Costs!C20+Assumptions!C$92+Costs!C25 -> 1018250 | D21: =Costs!D21+Costs!D22+Costs!D23+Costs!D20+Assumptions!D$92+Costs!D25 -> 1717125 | E21: =Costs!E21+Costs!E22+Costs!E23+Costs!E20+Assumptions!E$92+Costs!E25 -> 2756628.8 | F21: =Costs!F21+Costs!F22+Costs!F23+Costs!F20+Assumptions!F$92+Costs!F25 -> 4241476.4 | G21: =Costs!G21+Costs!G22+Costs!G23+Costs!G20+Assumptions!G$92+Costs!G25 -> 5852241.8
A22: Run-rate EBITDA if every live town were mature ($) | C22: =Rollout!C7/'Unit Economics'!$G$7*'Unit Economics'!$G$42-C21 -> -613580.35 | D22: =Rollout!D7/'Unit Economics'!$G$7*'Unit Economics'!$G$42-D21 -> 294083.18 | E22: =Rollout!E7/'Unit Economics'!$G$7*'Unit Economics'!$G$42-E21 -> 3244622.2 | F22: =Rollout!F7/'Unit Economics'!$G$7*'Unit Economics'!$G$42-F21 -> 9695346.4 | G22: =Rollout!G7/'Unit Economics'!$G$7*'Unit Economics'!$G$42-G21 -> 21904050 | H22: Live towns x Age 5 contribution per surviving town, less central costs: the profit the network already built would earn once its young towns mature, with no new launches.
A23: Mature towns needed to cover central costs | C23: =IF('Unit Economics'!$G$42<=0,0,C21/('Unit Economics'!$G$42/'Unit Economics'!$G$7)) -> 50.324999 | D23: =IF('Unit Economics'!$G$42<=0,0,D21/('Unit Economics'!$G$42/'Unit Economics'!$G$7)) -> 84.865519 | E23: =IF('Unit Economics'!$G$42<=0,0,E21/('Unit Economics'!$G$42/'Unit Economics'!$G$7)) -> 136.24094 | F23: =IF('Unit Economics'!$G$42<=0,0,F21/('Unit Economics'!$G$42/'Unit Economics'!$G$7)) -> 209.62661 | G23: =IF('Unit Economics'!$G$42<=0,0,G21/('Unit Economics'!$G$42/'Unit Economics'!$G$7)) -> 289.23552
A25: Single-town economics (from Unit Economics)
A26: Mature town revenue (Age 5, $/year) | C26: ='Unit Economics'!G25 -> 26374.633
A27: Mature town contribution (Age 5, $/year) | C27: ='Unit Economics'!G42 -> 18817.139
A28: Mature contribution margin | C28: ='Unit Economics'!G43 -> 0.71345594
A29: One-time launch cost per town ($) | C29: ='Unit Economics'!C44 -> 1540
A30: Town payback (age in years when cumulative contribution turns positive) | C30: =IFERROR(MATCH(TRUE(),INDEX('Unit Economics'!C45:G45>0,0),0),"After Age 5") -> 3 | H30: 1 = paid back within the launch year.
A31: First fiscal year with positive EBITDA | C31: =IFERROR(INDEX(C4:G4,MATCH(TRUE(),INDEX(C17:G17>0,0),0)),"Not by FY2031") -> Not by FY2031
A32: Equity needed (deepest cumulative free cash flow) | C32: ='Cash Flow'!C17 -> 18667394
